<?xml version="1.0" encoding="UTF-8"?>
<!-- Generated by org.testng.reporters.JUnitReportReporter -->
<testsuite skipped="0" hostname="LIN51007546" name="com.companyName.ProjectName.TestCases.Login_Test" tests="1" failures="1" timestamp="31 Oct 2020 03:46:23 GMT" time="18.636" errors="0">
  <testcase name="login_Test" time="18.636" classname="com.companyName.ProjectName.TestCases.Login_Test">
    <failure type="java.lang.AssertionError" message="expected [My Store] but found [automationpractice.com]">
      <![CDATA[java.lang.AssertionError: expected [My Store] but found [automationpractice.com]
	at org.testng.Assert.fail(Assert.java:93)
	at org.testng.Assert.failNotEquals(Assert.java:512)
	at org.testng.Assert.assertEqualsImpl(Assert.java:134)
	at org.testng.Assert.assertEquals(Assert.java:115)
	at org.testng.Assert.assertEquals(Assert.java:189)
	at org.testng.Assert.assertEquals(Assert.java:199)
	at com.companyName.ProjectName.TestCases.Login_Test.login_Test(Login_Test.java:32)
	at sun.reflect.NativeMethodAccessorImpl.invoke0(Native Method)
	at sun.reflect.NativeMethodAccessorImpl.invoke(NativeMethodAccessorImpl.java:62)
	at sun.reflect.DelegatingMethodAccessorImpl.invoke(DelegatingMethodAccessorImpl.java:43)
	at java.lang.reflect.Method.invoke(Method.java:498)
	at org.testng.internal.MethodInvocationHelper.invokeMethod(MethodInvocationHelper.java:108)
	at org.testng.internal.Invoker.invokeMethod(Invoker.java:661)
	at org.testng.internal.Invoker.invokeTestMethod(Invoker.java:869)
	at org.testng.internal.Invoker.invokeTestMethods(Invoker.java:1193)
	at org.testng.internal.TestMethodWorker.invokeTestMethods(TestMethodWorker.java:126)
	at org.testng.internal.TestMethodWorker.run(TestMethodWorker.java:109)
	at org.testng.TestRunner.privateRun(TestRunner.java:744)
	at org.testng.TestRunner.run(TestRunner.java:602)
	at org.testng.SuiteRunner.runTest(SuiteRunner.java:380)
	at org.testng.SuiteRunner.runSequentially(SuiteRunner.java:375)
	at org.testng.SuiteRunner.privateRun(SuiteRunner.java:340)
	at org.testng.SuiteRunner.run(SuiteRunner.java:289)
	at org.testng.SuiteRunnerWorker.runSuite(SuiteRunnerWorker.java:52)
	at org.testng.SuiteRunnerWorker.run(SuiteRunnerWorker.java:86)
	at org.testng.TestNG.runSuitesSequentially(TestNG.java:1301)
	at org.testng.TestNG.runSuitesLocally(TestNG.java:1226)
	at org.testng.TestNG.runSuites(TestNG.java:1144)
	at org.testng.TestNG.run(TestNG.java:1115)
	at org.testng.remote.AbstractRemoteTestNG.run(AbstractRemoteTestNG.java:132)
	at org.testng.remote.RemoteTestNG.initAndRun(RemoteTestNG.java:230)
	at org.testng.remote.RemoteTestNG.main(RemoteTestNG.java:76)
]]>
    </failure>
  </testcase> <!-- login_Test -->
</testsuite> <!-- com.companyName.ProjectName.TestCases.Login_Test -->
